Workbook
Name run_id: [1]!Table4[value]
Name run_id: Table4[value]

Sheet meta
A1: key | B1: value
A2: run_id | B2: MP7Y5R

Sheet biolectorlayout
A1: fp_well | B1: sample_id | C1: medium | D1: culture | E1: plasmid | F1: signal_peptide | G1: insert | H1: tag
A2: A01 | B2: =CONCATENATE(run_id,".",Table1[[#This Row],[fp_well]]) -> MP7Y5R.A01 | C2: CGXII | D2: VK | E2: =biolectorplate!B2 -> pCMEx8-PhoB-Lss-Stop | F2: PhoB | G2: Lss | H2: notag
A3: A02 | B3: =CONCATENATE(run_id,".",Table1[[#This Row],[fp_well]]) -> MP7Y5R.A02 | C3: CGXII | D3: HK | E3: =biolectorplate!C2 -> pCMEx8-PhoB-Lss-Stop | F3: PhoB | G3: Lss | H3: notag
A4: A03 | B4: =CONCATENATE(run_id,".",Table1[[#This Row],[fp_well]]) -> MP7Y5R.A03 | C4: CGXII | D4: VK | E4: =biolectorplate!D2 -> pCMEx8-YolA-Lss-Stop | F4: YolA | G4: Lss | H4: notag
A5: A04 | B5: =CONCATENATE(run_id,".",Table1[[#This Row],[fp_well]]) -> MP7Y5R.A04 | C5: CGXII | D5: HK | E5: =biolectorplate!E2 -> pCMEx8-YolA-Lss-Stop | F5: YolA | G5: Lss | H5: notag
A6: A05 | B6: =CONCATENATE(run_id,".",Table1[[#This Row],[fp_well]]) -> MP7Y5R.A05 | C6: CGXII | D6: HK | E6: =biolectorplate!F2 -> pCMEx8-NprE-DeimLss-Stop | F6: NprE | G6: DeimLss | H6: notag
A7: A06 | B7: =CONCATENATE(run_id,".",Table1[[#This Row],[fp_well]]) -> MP7Y5R.A06 | C7: CGXII | D7: VK | E7: =biolectorplate!G2 -> pCMEx8-NprE-DeimLss-Stop | F7: NprE | G7: DeimLss | H7: notag
A8: A07 | B8: =CONCATENATE(run_id,".",Table1[[#This Row],[fp_well]]) -> MP7Y5R.A07 | C8: CGXII | D8: HK | E8: =biolectorplate!H2 -> pCMEx8-YolA-DeimLss-Stop | F8: YolA | G8: DeimLss | H8: notag
A9: A08 | B9: =CONCATENATE(run_id,".",Table1[[#This Row],[fp_well]]) -> MP7Y5R.A08 | C9: CGXII | D9: VK | E9: =biolectorplate!I2 -> pCMEx8-YolA-DeimLss-Stop | F9: YolA | G9: DeimLss | H9: notag
A10: B01 | B10: =CONCATENATE(run_id,".",Table1[[#This Row],[fp_well]]) -> MP7Y5R.B01 | C10: CGXII | D10: VK | E10: =biolectorplate!B3 -> pCMEx8-PhoB-Lss-Stop | F10: PhoB | G10: Lss | H10: notag
A11: B02 | B11: =CONCATENATE(run_id,".",Table1[[#This Row],[fp_well]]) -> MP7Y5R.B02 | C11: CGXII | D11: HK | E11: =biolectorplate!C3 -> pCMEx8-PhoB-Lss-Stop | F11: PhoB | G11: Lss | H11: notag
A12: B03 | B12: =CONCATENATE(run_id,".",Table1[[#This Row],[fp_well]]) -> MP7Y5R.B03 | C12: CGXII | D12: VK | E12: =biolectorplate!D3 -> pCMEx8-YolA-Lss-Stop | F12: YolA | G12: Lss | H12: notag
A13: B04 | B13: =CONCATENATE(run_id,".",Table1[[#This Row],[fp_well]]) -> MP7Y5R.B04 | C13: CGXII | D13: HK | E13: =biolectorplate!E3 -> pCMEx8-YolA-Lss-Stop | F13: YolA | G13: Lss | H13: notag
A14: B05 | B14: =CONCATENATE(run_id,".",Table1[[#This Row],[fp_well]]) -> MP7Y5R.B05 | C14: CGXII | D14: HK | E14: =biolectorplate!F3 -> pCMEx8-NprE-DeimLss-Stop | F14: NprE | G14: DeimLss | H14: notag
A15: B06 | B15: =CONCATENATE(run_id,".",Table1[[#This Row],[fp_well]]) -> MP7Y5R.B06 | C15: CGXII | D15: VK | E15: =biolectorplate!G3 -> pCMEx8-NprE-DeimLss-Stop | F15: NprE | G15: DeimLss | H15: notag
A16: B07 | B16: =CONCATENATE(run_id,".",Table1[[#This Row],[fp_well]]) -> MP7Y5R.B07 | C16: CGXII | D16: HK | E16: =biolectorplate!H3 -> pCMEx8-YwaD-DeimLss-Stop | F16: YwaD | G16: DeimLss | H16: notag
A17: B08 | B17: =CONCATENATE(run_id,".",Table1[[#This Row],[fp_well]]) -> MP7Y5R.B08 | C17: CGXII | D17: VK | E17: =biolectorplate!I3 -> pCMEx8-YwaD-DeimLss-Stop | F17: YwaD | G17: DeimLss | H17: notag
A18: C01 | B18: =CONCATENATE(run_id,".",Table1[[#This Row],[fp_well]]) -> MP7Y5R.C01 | C18: CGXII | D18: VK | E18: =biolectorplate!B4 -> pCMEx8-YoaW-Lss-Stop | F18: YoaW | G18: Lss | H18: notag
A19: C02 | B19: =CONCATENATE(run_id,".",Table1[[#This Row],[fp_well]]) -> MP7Y5R.C02 | C19: CGXII | D19: HK | E19: =biolectorplate!C4 -> pCMEx8-YoaW-Lss-Stop | F19: YoaW | G19: Lss | H19: notag
A20: C03 | B20: =CONCATENATE(run_id,".",Table1[[#This Row],[fp_well]]) -> MP7Y5R.C03 | C20: CGXII | D20: VK | E20: =biolectorplate!D4 -> pCMEx8-YwaD-Lss-Stop | F20: YwaD | G20: Lss | H20: notag
A21: C04 | B21: =CONCATENATE(run_id,".",Table1[[#This Row],[fp_well]]) -> MP7Y5R.C04 | C21: CGXII | D21: HK | E21: =biolectorplate!E4 -> pCMEx8-YwaD-Lss-Stop | F21: YwaD | G21: Lss | H21: notag
A22: C05 | B22: =CONCATENATE(run_id,".",Table1[[#This Row],[fp_well]]) -> MP7Y5R.C05 | C22: CGXII | D22: HK | E22: =biolectorplate!F4 -> pCMEx8-NprE-DeimLss-Stop | F22: NprE | G22: DeimLss | H22: notag
A23: C06 | B23: =CONCATENATE(run_id,".",Table1[[#This Row],[fp_well]]) -> MP7Y5R.C06 | C23: CGXII | D23: VK | E23: =biolectorplate!G4 -> pCMEx8-NprE-DeimLss-Stop | F23: NprE | G23: DeimLss | H23: notag
A24: C07 | B24: =CONCATENATE(run_id,".",Table1[[#This Row],[fp_well]]) -> MP7Y5R.C07 | C24: CGXII | D24: HK | E24: =biolectorplate!H4 -> pCMEx8-YwaD-DeimLss-Stop | F24: YwaD | G24: DeimLss | H24: notag
A25: C08 | B25: =CONCATENATE(run_id,".",Table1[[#This Row],[fp_well]]) -> MP7Y5R.C08 | C25: CGXII | D25: VK | E25: =biolectorplate!I4 -> pCMEx8-YwaD-DeimLss-Stop | F25: YwaD | G25: DeimLss | H25: notag
A26: D01 | B26: =CONCATENATE(run_id,".",Table1[[#This Row],[fp_well]]) -> MP7Y5R.D01 | C26: CGXII | D26: VK | E26: =biolectorplate!B5 -> pCMEx8-YoaW-Lss-Stop | F26: YoaW | G26: Lss | H26: notag
A27: D02 | B27: =CONCATENATE(run_id,".",Table1[[#This Row],[fp_well]]) -> MP7Y5R.D02 | C27: CGXII | D27: HK | E27: =biolectorplate!C5 -> pCMEx8-YoaW-Lss-Stop | F27: YoaW | G27: Lss | H27: notag
A28: D03 | B28: =CONCATENATE(run_id,".",Table1[[#This Row],[fp_well]]) -> MP7Y5R.D03 | C28: CGXII | D28: VK | E28: =biolectorplate!D5 -> pCMEx8-YwaD-Lss-Stop | F28: YwaD | G28: Lss | H28: notag
A29: D04 | B29: =CONCATENATE(run_id,".",Table1[[#This Row],[fp_well]]) -> MP7Y5R.D04 | C29: CGXII | D29: HK | E29: =biolectorplate!E5 -> pCMEx8-YwaD-Lss-Stop | F29: YwaD | G29: Lss | H29: notag
A30: D05 | B30: =CONCATENATE(run_id,".",Table1[[#This Row],[fp_well]]) -> MP7Y5R.D05 | C30: CGXII | D30: HK | E30: =biolectorplate!F5 -> pCMEx8-NprE-DeimLss-Stop | F30: NprE | G30: DeimLss | H30: notag
A31: D06 | B31: =CONCATENATE(run_id,".",Table1[[#This Row],[fp_well]]) -> MP7Y5R.D06 | C31: CGXII | D31: VK | E31: =biolectorplate!G5 -> pCMEx8-NprE-DeimLss-Stop | F31: NprE | G31: DeimLss | H31: notag
A32: D07 | B32: =CONCATENATE(run_id,".",Table1[[#This Row],[fp_well]]) -> MP7Y5R.D07 | C32: CGXII | D32: HK | E32: =biolectorplate!H5 -> pCMEx8-YwaD-DeimLss-Stop | F32: YwaD | G32: DeimLss | H32: notag
A33: D08 | B33: =CONCATENATE(run_id,".",Table1[[#This Row],[fp_well]]) -> MP7Y5R.D08 | C33: CGXII | D33: VK | E33: =biolectorplate!I5 -> pCMEx8-YwaD-DeimLss-Stop | F33: YwaD | G33: DeimLss | H33: notag
A34: E01 | B34: =CONCATENATE(run_id,".",Table1[[#This Row],[fp_well]]) -> MP7Y5R.E01 | C34: CGXII | D34: VK | E34: =biolectorplate!B6 -> pCMEx8-YolA-Lss-Stop | F34: YolA | G34: Lss | H34: notag
A35: E02 | B35: =CONCATENATE(run_id,".",Table1[[#This Row],[fp_well]]) -> MP7Y5R.E02 | C35: CGXII | D35: HK | E35: =biolectorplate!C6 -> pCMEx8-YolA-Lss-Stop | F35: YolA | G35: Lss | H35: notag
A36: E03 | B36: =CONCATENATE(run_id,".",Table1[[#This Row],[fp_well]]) -> MP7Y5R.E03 | C36: CGXII | D36: VK | E36: =biolectorplate!D6 -> pCMEx8-YolA-Lss-GFP11 | F36: YolA | G36: Lss | H36: GFP11
A37: E04 | B37: =CONCATENATE(run_id,".",Table1[[#This Row],[fp_well]]) -> MP7Y5R.E04 | C37: CGXII | D37: HK | E37: =biolectorplate!E6 -> pCMEx8-YolA-Lss-GFP11 | F37: YolA | G37: Lss | H37: GFP11
A38: E05 | B38: =CONCATENATE(run_id,".",Table1[[#This Row],[fp_well]]) -> MP7Y5R.E05 | C38: CGXII | D38: HK | E38: =biolectorplate!F6 -> pCMEx8-YolA-DeimLss-Stop | F38: YolA | G38: DeimLss | H38: notag
A39: E06 | B39: =CONCATENATE(run_id,".",Table1[[#This Row],[fp_well]]) -> MP7Y5R.E06 | C39: CGXII | D39: VK | E39: =biolectorplate!G6 -> pCMEx8-YolA-DeimLss-Stop | F39: YolA | G39: DeimLss | H39: notag
A40: E07 | B40: =CONCATENATE(run_id,".",Table1[[#This Row],[fp_well]]) -> MP7Y5R.E07 | C40: CGXII | D40: HK | E40: =biolectorplate!H6 -> pCMEx8-YwaD-DeimLss-Stop | F40: YwaD | G40: DeimLss | H40: notag
...

Sheet biolectorplate
B1: 1 | C1: 2 | D1: 3 | E1: 4 | F1: 5 | G1: 6 | H1: 7 | I1: 8
A2: A | B2: pCMEx8-PhoB-Lss-Stop | C2: pCMEx8-PhoB-Lss-Stop | D2: pCMEx8-YolA-Lss-Stop | E2: pCMEx8-YolA-Lss-Stop | F2: pCMEx8-NprE-DeimLss-Stop | G2: pCMEx8-NprE-DeimLss-Stop | H2: pCMEx8-YolA-DeimLss-Stop | I2: pCMEx8-YolA-DeimLss-Stop
A3: B | B3: pCMEx8-PhoB-Lss-Stop | C3: pCMEx8-PhoB-Lss-Stop | D3: pCMEx8-YolA-Lss-Stop | E3: pCMEx8-YolA-Lss-Stop | F3: pCMEx8-NprE-DeimLss-Stop | G3: pCMEx8-NprE-DeimLss-Stop | H3: pCMEx8-YwaD-DeimLss-Stop | I3: pCMEx8-YwaD-DeimLss-Stop
A4: C | B4: pCMEx8-YoaW-Lss-Stop | C4: pCMEx8-YoaW-Lss-Stop | D4: pCMEx8-YwaD-Lss-Stop | E4: pCMEx8-YwaD-Lss-Stop | F4: pCMEx8-NprE-DeimLss-Stop | G4: pCMEx8-NprE-DeimLss-Stop | H4: pCMEx8-YwaD-DeimLss-Stop | I4: pCMEx8-YwaD-DeimLss-Stop
A5: D | B5: pCMEx8-YoaW-Lss-Stop | C5: pCMEx8-YoaW-Lss-Stop | D5: pCMEx8-YwaD-Lss-Stop | E5: pCMEx8-YwaD-Lss-Stop | F5: pCMEx8-NprE-DeimLss-Stop | G5: pCMEx8-NprE-DeimLss-Stop | H5: pCMEx8-YwaD-DeimLss-Stop | I5: pCMEx8-YwaD-DeimLss-Stop
A6: E | B6: pCMEx8-YolA-Lss-Stop | C6: pCMEx8-YolA-Lss-Stop | D6: pCMEx8-YolA-Lss-GFP11 | E6: pCMEx8-YolA-Lss-GFP11 | F6: pCMEx8-YolA-DeimLss-Stop | G6: pCMEx8-YolA-DeimLss-Stop | H6: pCMEx8-YwaD-DeimLss-Stop | I6: pCMEx8-YwaD-DeimLss-Stop
A7: F | B7: pCMEx8-YolA-Lss-Stop | C7: pCMEx8-YolA-Lss-Stop | D7: pCMEx8-Bsn-DeimLss-Stop | E7: pCMEx8-Bsn-DeimLss-Stop | F7: pCMEx8-YolA-DeimLss-Stop | G7: pCMEx8-YolA-DeimLss-Stop | H7: pCMEx8-NprE-Cutinase-GFP11 | I7: pCMEx8-NprE-Cutinase-GFP11
B8: VK | C8: HK | D8: VK | E8: HK | F8: HK | G8: VK | H8: HK | I8: VK

Sheet sGFPlayout
A1: sgfp_well | B1: content | C1: sample_id | D1: sample_type
A2: A01
A3: A02
A4: A03
A5: A04
A6: A05
A7: A06 | B7: Std 5 µM | C7: Std 5 µM | D7: Standard
A8: A07 | B8: Std 5 µM | C8: Std 5 µM | D8: Standard
A9: A08
A10: A09
A11: A10
A12: A11
A13: A12
A14: B01
A15: B02 | B15: =biolectorlayout!E3 -> pCMEx8-PhoB-Lss-Stop | C15: =biolectorlayout!B3 -> MP7Y5R.A02 | D15: xSample
A16: B03 | B16: =biolectorlayout!E5 -> pCMEx8-YolA-Lss-Stop | C16: =biolectorlayout!B5 -> MP7Y5R.A04 | D16: xSample
A17: B04 | B17: =biolectorlayout!E6 -> pCMEx8-NprE-DeimLss-Stop | C17: =biolectorlayout!B6 -> MP7Y5R.A05 | D17: xSample
A18: B05 | B18: =biolectorlayout!E8 -> pCMEx8-YolA-DeimLss-Stop | C18: =biolectorlayout!B8 -> MP7Y5R.A07 | D18: xSample
A19: B06 | B19: Std 2.5 µM | C19: Std 2.5 µM | D19: Standard
A20: B07 | B20: Std 2.5 µM | C20: Std 2.5 µM | D20: Standard
A21: B08 | B21: =B15 -> pCMEx8-PhoB-Lss-Stop | C21: =C15 -> MP7Y5R.A02 | D21: xSample
A22: B09 | B22: =B16 -> pCMEx8-YolA-Lss-Stop | C22: =C16 -> MP7Y5R.A04 | D22: xSample
A23: B10 | B23: =B17 -> pCMEx8-NprE-DeimLss-Stop | C23: =C17 -> MP7Y5R.A05 | D23: xSample
A24: B11 | B24: =B18 -> pCMEx8-YolA-DeimLss-Stop | C24: =C18 -> MP7Y5R.A07 | D24: xSample
A25: B12
A26: C01
A27: C02 | B27: =biolectorlayout!E11 -> pCMEx8-PhoB-Lss-Stop | C27: =biolectorlayout!B11 -> MP7Y5R.B02 | D27: xSample
A28: C03 | B28: =biolectorlayout!E13 -> pCMEx8-YolA-Lss-Stop | C28: =biolectorlayout!B13 -> MP7Y5R.B04 | D28: xSample
A29: C04 | B29: =biolectorlayout!E14 -> pCMEx8-NprE-DeimLss-Stop | C29: =biolectorlayout!B14 -> MP7Y5R.B05 | D29: xSample
A30: C05 | B30: =biolectorlayout!E16 -> pCMEx8-YwaD-DeimLss-Stop | C30: =biolectorlayout!B16 -> MP7Y5R.B07 | D30: xSample
A31: C06 | B31: Std 1.25 µM | C31: Std 1.25 µM | D31: Standard
A32: C07 | B32: Std 1.25 µM | C32: Std 1.25 µM | D32: Standard
A33: C08 | B33: =B27 -> pCMEx8-PhoB-Lss-Stop | C33: =C27 -> MP7Y5R.B02 | D33: xSample
A34: C09 | B34: =B28 -> pCMEx8-YolA-Lss-Stop | C34: =C28 -> MP7Y5R.B04 | D34: xSample
A35: C10 | B35: =B29 -> pCMEx8-NprE-DeimLss-Stop | C35: =C29 -> MP7Y5R.B05 | D35: xSample
A36: C11 | B36: =B30 -> pCMEx8-YwaD-DeimLss-Stop | C36: =C30 -> MP7Y5R.B07 | D36: xSample
A37: C12
A38: D01
A39: D02 | B39: =biolectorlayout!E19 -> pCMEx8-YoaW-Lss-Stop | C39: =biolectorlayout!B19 -> MP7Y5R.C02 | D39: xSample
A40: D03 | B40: =biolectorlayout!E21 -> pCMEx8-YwaD-Lss-Stop | C40: =biolectorlayout!B21 -> MP7Y5R.C04 | D40: xSample
...

Sheet sGFPstandards
A1: sample_id | B1: gfp_concentration
A2: Std 0.039 µM | B2: 0.039
A3: Std 0.078 µM | B3: 0.078
A4: Std 0.156 µM | B4: 0.156
A5: Std 0.316 µM | B5: 0.316
A6: Std 0.625 µM | B6: 0.625
A7: Std 1.25 µM | B7: 1.25
A8: Std 2.5 µM | B8: 2.5
A9: Std 5 µM | B9: 5

Sheet turbiditylayout
A1: turbidity_plate | B1: turbidity_well | C1: content | D1: sample_id | E1: sample_type | F1: dilution_factor
A2: plate_1 | B2: A01 | C2: Std 10 µg/mL | D2: Std 10 µg/mL | E2: Standard | F2: 1
A3: plate_1 | B3: A02 | C3: Std 10 µg/mL | D3: Std 10 µg/mL | E3: Standard | F3: 1
A4: plate_1 | B4: A03 | C4: Std 10 µg/mL | D4: Std 10 µg/mL | E4: Standard | F4: 1
A5: plate_1 | B5: A04 | C5: =biolectorlayout!E3 -> pCMEx8-PhoB-Lss-Stop | D5: =biolectorlayout!B3 -> MP7Y5R.A02 | E5: xSample | F5: 1
A6: plate_1 | B6: A05 | C6: =biolectorlayout!E21 -> pCMEx8-YwaD-Lss-Stop | D6: =biolectorlayout!B21 -> MP7Y5R.C04 | E6: xSample | F6: 1
A7: plate_1 | B7: A06 | C7: =biolectorlayout!E38 -> pCMEx8-YolA-DeimLss-Stop | D7: =biolectorlayout!B38 -> MP7Y5R.E05 | E7: xSample | F7: 1
A14: plate_1 | B14: B01 | C14: Std 5 µg/mL | D14: Std 5 µg/mL | E14: Standard | F14: 1
A15: plate_1 | B15: B02 | C15: Std 5 µg/mL | D15: Std 5 µg/mL | E15: Standard | F15: 1
A16: plate_1 | B16: B03 | C16: Std 5 µg/mL | D16: Std 5 µg/mL | E16: Standard | F16: 1
A17: plate_1 | B17: B04 | C17: =biolectorlayout!E11 -> pCMEx8-PhoB-Lss-Stop | D17: =biolectorlayout!B11 -> MP7Y5R.B02 | E17: xSample | F17: 1
A18: plate_1 | B18: B05 | C18: =biolectorlayout!E29 -> pCMEx8-YwaD-Lss-Stop | D18: =biolectorlayout!B29 -> MP7Y5R.D04 | E18: xSample | F18: 1
A19: plate_1 | B19: B06 | C19: =biolectorlayout!E46 -> pCMEx8-YolA-DeimLss-Stop | D19: =biolectorlayout!B46 -> MP7Y5R.F05 | E19: xSample | F19: 1
A26: plate_1 | B26: C01 | C26: Std 2.5 µg/mL | D26: Std 2.5 µg/mL | E26: Standard | F26: 1
A27: plate_1 | B27: C02 | C27: Std 2.5 µg/mL | D27: Std 2.5 µg/mL | E27: Standard | F27: 1
A28: plate_1 | B28: C03 | C28: Std 2.5 µg/mL | D28: Std 2.5 µg/mL | E28: Standard | F28: 1
A29: plate_1 | B29: C04 | C29: =biolectorlayout!E19 -> pCMEx8-YoaW-Lss-Stop | D29: =biolectorlayout!B19 -> MP7Y5R.C02 | E29: xSample | F29: 1
A30: plate_1 | B30: C05 | C30: =biolectorlayout!E37 -> pCMEx8-YolA-Lss-GFP11 | D30: =biolectorlayout!B37 -> MP7Y5R.E04 | E30: xSample | F30: 1
A31: plate_1 | B31: C06 | C31: =biolectorlayout!E8 -> pCMEx8-YolA-DeimLss-Stop | D31: =biolectorlayout!B8 -> MP7Y5R.A07 | E31: xSample | F31: 1
A38: plate_1 | B38: D01 | C38: Std 1.25 µg/mL | D38: Std 1.25 µg/mL | E38: Standard | F38: 1
A39: plate_1 | B39: D02 | C39: Std 1.25 µg/mL | D39: Std 1.25 µg/mL | E39: Standard | F39: 1
A40: plate_1 | B40: D03 | C40: Std 1.25 µg/mL | D40: Std 1.25 µg/mL | E40: Standard | F40: 1
A41: plate_1 | B41: D04 | C41: =biolectorlayout!E27 -> pCMEx8-YoaW-Lss-Stop | D41: =biolectorlayout!B27 -> MP7Y5R.D02 | E41: xSample | F41: 1
A42: plate_1 | B42: D05 | C42: =biolectorlayout!E45 -> pCMEx8-Bsn-DeimLss-Stop | D42: =biolectorlayout!B45 -> MP7Y5R.F04 | E42: xSample | F42: 1
A43: plate_1 | B43: D06 | C43: =biolectorlayout!E16 -> pCMEx8-YwaD-DeimLss-Stop | D43: =biolectorlayout!B16 -> MP7Y5R.B07 | E43: xSample | F43: 1
A50: plate_1 | B50: E01 | C50: Std 0.625 µg/mL | D50: Std 0.625 µg/mL | E50: Standard | F50: 1
A51: plate_1 | B51: E02 | C51: Std 0.625 µg/mL | D51: Std 0.625 µg/mL | E51: Standard | F51: 1
A52: plate_1 | B52: E03 | C52: Std 0.625 µg/mL | D52: Std 0.625 µg/mL | E52: Standard | F52: 1
A53: plate_1 | B53: E04 | C53: =biolectorlayout!E35 -> pCMEx8-YolA-Lss-Stop | D53: =biolectorlayout!B35 -> MP7Y5R.E02 | E53: xSample | F53: 1
A54: plate_1 | B54: E05 | C54: =biolectorlayout!E6 -> pCMEx8-NprE-DeimLss-Stop | D54: =biolectorlayout!B6 -> MP7Y5R.A05 | E54: xSample | F54: 1
A55: plate_1 | B55: E06 | C55: =biolectorlayout!E24 -> pCMEx8-YwaD-DeimLss-Stop | D55: =biolectorlayout!B24 -> MP7Y5R.C07 | E55: xSample | F55: 1
A62: plate_1 | B62: F01 | C62: Std 0.313 µg/mL | D62: Std 0.313 µg/mL | E62: Standard | F62: 1
A63: plate_1 | B63: F02 | C63: Std 0.313 µg/mL | D63: Std 0.313 µg/mL | E63: Standard | F63: 1
A64: plate_1 | B64: F03 | C64: Std 0.313 µg/mL | D64: Std 0.313 µg/mL | E64: Standard | F64: 1
A65: plate_1 | B65: F04 | C65: =biolectorlayout!E43 -> pCMEx8-YolA-Lss-Stop | D65: =biolectorlayout!B43 -> MP7Y5R.F02 | E65: xSample | F65: 1
A66: plate_1 | B66: F05 | C66: =biolectorlayout!E14 -> pCMEx8-NprE-DeimLss-Stop | D66: =biolectorlayout!B14 -> MP7Y5R.B05 | E66: xSample | F66: 1
A67: plate_1 | B67: F06 | C67: =biolectorlayout!E32 -> pCMEx8-YwaD-DeimLss-Stop | D67: =biolectorlayout!B32 -> MP7Y5R.D07 | E67: xSample | F67: 1
A74: plate_1 | B74: G01 | C74: Std 0.156 µg/mL | D74: Std 0.156 µg/mL | E74: Standard | F74: 1
A75: plate_1 | B75: G02 | C75: Std 0.156 µg/mL | D75: Std 0.156 µg/mL | E75: Standard | F75: 1
A76: plate_1 | B76: G03 | C76: Std 0.156 µg/mL | D76: Std 0.156 µg/mL | E76: Standard | F76: 1
...

Sheet turbiditystandards
A1: sample_id | B1: lss_concentration in µg/mL | C1: lss_concentration in µM
A2: Std 0 µg/mL | B2: 0 | C2: =Tabelle78[[#This Row],[lss_concentration in µg/mL]]/26.94426 -> 0
A3: Std 0.156 µg/mL | B3: 0.156 | C3: =Tabelle78[[#This Row],[lss_concentration in µg/mL]]/26.94426 -> 0.0057897304
A4: Std 0.313 µg/mL | B4: 0.313 | C4: =Tabelle78[[#This Row],[lss_concentration in µg/mL]]/26.94426 -> 0.011616574
A5: Std 0.625 µg/mL | B5: 0.625 | C5: =Tabelle78[[#This Row],[lss_concentration in µg/mL]]/26.94426 -> 0.023196035
A6: Std 1.25 µg/mL | B6: 1.25 | C6: =Tabelle78[[#This Row],[lss_concentration in µg/mL]]/26.94426 -> 0.04639207
A7: Std 2.5 µg/mL | B7: 2.5 | C7: =Tabelle78[[#This Row],[lss_concentration in µg/mL]]/26.94426 -> 0.09278414
A8: Std 5 µg/mL | B8: 5 | C8: =Tabelle78[[#This Row],[lss_concentration in µg/mL]]/26.94426 -> 0.18556828
A9: Std 10 µg/mL | B9: 10 | C9: =Tabelle78[[#This Row],[lss_concentration in µg/mL]]/26.94426 -> 0.37113656
